Workbook

Sheet ✅ Closing Checklist
A1: MONATSABSCHLUSS-CHECKLISTE / MONTHLY CLOSING CHECKLIST
A2: RetailCo Financial Analysis | Bike Sales 2011–2016
A3: Berichtsperiode / Reporting Period: | D3: 2015-12 | E3: ← Hier Periode eingeben / Enter period here
A5: # | B5: Aufgabe (DE) / Task (EN) | C5: Beschreibung / Description | D5: Verantw. / Responsible | E5: Fällig / Due | F5: Herkunft / Data Source | G5: Status | H5: Kommentar / Comment
A6: 1 | B6: Rohdaten prüfen Verify raw data | C6: Vollständigkeit & Qualität der Transaktionsdaten / Completeness & quality of transaction data | D6: Buchhalter / Accountant | E6: WD-3 | F6: bike_sales_clean.csv (Modul 0 Output) | G6: ✅ Erledigt
A7: 2 | B7: Umsatzabstimmung Revenue reconciliation | C7: Summe aller Transaktionen = aggregierter Monatsumsatz; prüfen ob tx_revenue == agg_revenue (Δ = 0) | D7: Buchhalter / Accountant | E7: WD-2 | F7: df['revenue'].sum() vs. monthly['Umsatz_Ist'].sum() | G7: ✅ Erledigt
A8: 3 | B8: Kostenabstimmung Cost reconciliation | C8: COGS Transaktionen vs. Hauptbuch; df['cost'].sum() == monthly['Kosten_Ist'].sum() | D8: Buchhalter / Accountant | E8: WD-2 | F8: df['cost'].sum() vs. monthly['Kosten_Ist'].sum() | G8: ✅ Erledigt
A9: 4 | B9: Rechnungsabgrenzung Accruals posting | C9: ARAP = 5% × Umsatz_Ist (aktive Abgrenzung / prepaid) PRAP = 3% × Kosten_Ist (passive Abgrenzung / deferred) Ergebnis_bereinigt = Ergebnis – ARAP + PRAP | D9: Buchhalter / Accountant | E9: WD-1 | F9: Modul 1 Zelle: ARAP_RATE=0.05 PRAP_RATE=0.03 | G9: ✅ Erledigt
A10: 5 | B10: Plan-Ist-Abgleich Budget vs. Actual | C10: Abweichung % = (Ist − Plan) / Plan × 100 Materialitätsschwelle: ≥5% → Kommentarpflicht RAG: Grün ≥3%, Amber −3%..+3%, Rot <−3% | D10: Controller | E10: WD-1 | F10: monthly['Umsatz_Abw_pct'] = (Ist−Plan)/Plan×100 | G10: ✅ Erledigt
A11: 6 | B11: GuV erstellen Prepare P&L | C11: Monatliche GuV im Format: Umsatz − COGS = Bruttoergebnis Bruttomarge % = Bruttoergebnis / Umsatz | D11: Controller | E11: WD-1 | F11: Sheet 'Monthly P&L' dieses Workbooks | G11: ✅ Erledigt
A12: 7 | B12: Management Review | C12: Freigabe durch CFO / Sign-off by CFO Prüfung Abweichungskommentare und RAG-Status | D12: CFO / Leitung | E12: WD 0 | F12: Abweichungskommentare aus Modul 1 Zelle 6 | G12: ✅ Erledigt
A13: 8 | B13: Bericht versenden Distribute report | C13: Management Summary an Stakeholder / Send summary to stakeholders | D13: Controller | E13: WD 0 | F13: management_summary _DE/EN.pdf | G13: ✅ Erledigt
A14: 9 | B14: Archivierung Archive | C14: Alle Belege & Reports ins Archiv / All documents & reports to archive | D14: Buchhalter / Accountant | E14: WD+1 | F14: closing_checklist.xlsx + alle Outputs | G14: ✅ Erledigt
A16: Legende / Legend: ✅ Erledigt/Done 🔄 In Bearbeitung/In Progress ⏳ Pending/Ausstehend ❌ Offen/Open | WD = Arbeitstag / Working Day (WD-3 = 3 Tage vor Abschluss / 3 days before closing) | Herkunft = Datenquelle/Formel aus Notebook / Data source & formula from Notebook

Sheet 📊 Monthly P&L (GuV)
A1: MONATLICHE GEWINN- UND VERLUSTRECHNUNG / MONTHLY PROFIT & LOSS STATEMENT
A2: RetailCo Financial Analysis | Bike Sales 2011–2016 | Alle Beträge in USD / All amounts in USD
A4: Formeln: GP=Umsatz−COGS | Marge%=GP/Umsatz | Abw.abs=Ist−Plan | Abw.%=Abw.abs/Plan | ARAP=Umsatz×5% | PRAP=COGS×3% | Berein.Erg=GP−ARAP+PRAP | RAG: 🟢≥+3% 🟡±3% 🔴<-3% → Details siehe Sheet '📖 Legende & Formeln'
A5: Farbcode: 🔵 Blau = Eingabe aus Rohdaten/CSV | 🟢 Grün = Excel-Formel | 🟡 Gelb = Summenzeile | Datenquelle: bike_sales_clean.csv via Modul 1 Notebook
A6: GJ/FY | B6: Periode/Period | C6: Umsatz_Ist (Revenue) | D6: COGS_Ist (Costs) | E6: Bruttoerg. (Gross Profit) | F6: Brutto- marge % | G6: Plan (Budget) | H6: Abw.abs (Var.abs) | I6: Abw.% (Var.%) | J6: RAG | K6: ARAP (5% Umsatz) | L6: PRAP (3% COGS) | M6: Erg.bereinigt (Adj.Result)
A7: 2015 | B7: 2015-01 | C7: 666938 | D7: 447744 | E7: =C7-D7 -> 219194 | F7: =IF(C7<>0,E7/C7,0) -> 0.32865724 | G7: 665780 | H7: =C7-G7 -> 1158 | I7: =IF(G7<>0,H7/G7,0) -> 0.0017393133 | J7: =IF(I7>=0.03,"🟢",IF(I7>=-0.03,"🟡","🔴")) -> 🟡 | K7: =ROUND(C7*0.05,0) -> 33347 | L7: =ROUND(D7*0.03,0) -> 13432 | M7: =E7-K7+L7 -> 199279
A8: 2015 | B8: 2015-02 | C8: 679246 | D8: 458635 | E8: =C8-D8 -> 220611 | F8: =IF(C8<>0,E8/C8,0) -> 0.32478807 | G8: 672878 | H8: =C8-G8 -> 6368 | I8: =IF(G8<>0,H8/G8,0) -> 0.0094638255 | J8: =IF(I8>=0.03,"🟢",IF(I8>=-0.03,"🟡","🔴")) -> 🟡 | K8: =ROUND(C8*0.05,0) -> 33962 | L8: =ROUND(D8*0.03,0) -> 13759 | M8: =E8-K8+L8 -> 200408
A9: 2015 | B9: 2015-03 | C9: 714008 | D9: 477922 | E9: =C9-D9 -> 236086 | F9: =IF(C9<>0,E9/C9,0) -> 0.33064896 | G9: 712079 | H9: =C9-G9 -> 1929 | I9: =IF(G9<>0,H9/G9,0) -> 0.0027089691 | J9: =IF(I9>=0.03,"🟢",IF(I9>=-0.03,"🟡","🔴")) -> 🟡 | K9: =ROUND(C9*0.05,0) -> 35700 | L9: =ROUND(D9*0.03,0) -> 14338 | M9: =E9-K9+L9 -> 214724
A10: 2015 | B10: 2015-04 | C10: 734608 | D10: 497020 | E10: =C10-D10 -> 237588 | F10: =IF(C10<>0,E10/C10,0) -> 0.32342147 | G10: 728736 | H10: =C10-G10 -> 5872 | I10: =IF(G10<>0,H10/G10,0) -> 0.0080577877 | J10: =IF(I10>=0.03,"🟢",IF(I10>=-0.03,"🟡","🔴")) -> 🟡 | K10: =ROUND(C10*0.05,0) -> 36730 | L10: =ROUND(D10*0.03,0) -> 14911 | M10: =E10-K10+L10 -> 215769
A11: 2015 | B11: 2015-05 | C11: 895043 | D11: 597749 | E11: =C11-D11 -> 297294 | F11: =IF(C11<>0,E11/C11,0) -> 0.33215611 | G11: 901206 | H11: =C11-G11 -> -6163 | I11: =IF(G11<>0,H11/G11,0) -> -0.006838614 | J11: =IF(I11>=0.03,"🟢",IF(I11>=-0.03,"🟡","🔴")) -> 🟡 | K11: =ROUND(C11*0.05,0) -> 44752 | L11: =ROUND(D11*0.03,0) -> 17932 | M11: =E11-K11+L11 -> 270474
A12: 2015 | B12: 2015-06 | C12: 786480 | D12: 527616 | E12: =C12-D12 -> 258864 | F12: =IF(C12<>0,E12/C12,0) -> 0.32914251 | G12: 786483 | H12: =C12-G12 -> -3 | I12: =IF(G12<>0,H12/G12,0) -> -3.8144499e-06 | J12: =IF(I12>=0.03,"🟢",IF(I12>=-0.03,"🟡","🔴")) -> 🟡 | K12: =ROUND(C12*0.05,0) -> 39324 | L12: =ROUND(D12*0.03,0) -> 15828 | M12: =E12-K12+L12 -> 235368
A13: 2015 | B13: 2015-07 | C13: 1728398 | D13: 1118446 | E13: =C13-D13 -> 609952 | F13: =IF(C13<>0,E13/C13,0) -> 0.3529002 | G13: 1721640 | H13: =C13-G13 -> 6758 | I13: =IF(G13<>0,H13/G13,0) -> 0.003925327 | J13: =IF(I13>=0.03,"🟢",IF(I13>=-0.03,"🟡","🔴")) -> 🟡 | K13: =ROUND(C13*0.05,0) -> 86420 | L13: =ROUND(D13*0.03,0) -> 33553 | M13: =E13-K13+L13 -> 557085
A14: 2015 | B14: 2015-08 | C14: 2140581 | D14: 1264046 | E14: =C14-D14 -> 876535 | F14: =IF(C14<>0,E14/C14,0) -> 0.40948462 | G14: 2139961 | H14: =C14-G14 -> 620 | I14: =IF(G14<>0,H14/G14,0) -> 0.00028972491 | J14: =IF(I14>=0.03,"🟢",IF(I14>=-0.03,"🟡","🔴")) -> 🟡 | K14: =ROUND(C14*0.05,0) -> 107029 | L14: =ROUND(D14*0.03,0) -> 37921 | M14: =E14-K14+L14 -> 807427
A15: 2015 | B15: 2015-09 | C15: 2465172 | D15: 1478781 | E15: =C15-D15 -> 986391 | F15: =IF(C15<>0,E15/C15,0) -> 0.4001307 | G15: 2459901 | H15: =C15-G15 -> 5271 | I15: =IF(G15<>0,H15/G15,0) -> 0.0021427692 | J15: =IF(I15>=0.03,"🟢",IF(I15>=-0.03,"🟡","🔴")) -> 🟡 | K15: =ROUND(C15*0.05,0) -> 123259 | L15: =ROUND(D15*0.03,0) -> 44363 | M15: =E15-K15+L15 -> 907495
A16: 2015 | B16: 2015-10 | C16: 2529084 | D16: 1528465 | E16: =C16-D16 -> 1000619 | F16: =IF(C16<>0,E16/C16,0) -> 0.39564483 | G16: 2538826 | H16: =C16-G16 -> -9742 | I16: =IF(G16<>0,H16/G16,0) -> -0.0038372066 | J16: =IF(I16>=0.03,"🟢",IF(I16>=-0.03,"🟡","🔴")) -> 🟡 | K16: =ROUND(C16*0.05,0) -> 126454 | L16: =ROUND(D16*0.03,0) -> 45854 | M16: =E16-K16+L16 -> 920019
A17: 2015 | B17: 2015-11 | C17: 2836222 | D17: 1730335 | E17: =C17-D17 -> 1105887 | F17: =IF(C17<>0,E17/C17,0) -> 0.38991553 | G17: 2835230 | H17: =C17-G17 -> 992 | I17: =IF(G17<>0,H17/G17,0) -> 0.00034988343 | J17: =IF(I17>=0.03,"🟢",IF(I17>=-0.03,"🟡","🔴")) -> 🟡 | K17: =ROUND(C17*0.05,0) -> 141811 | L17: =ROUND(D17*0.03,0) -> 51910 | M17: =E17-K17+L17 -> 1015986
A18: 2015 | B18: 2015-12 | C18: 3848211 | D18: 2368669 | E18: =C18-D18 -> 1479542 | F18: =IF(C18<>0,E18/C18,0) -> 0.38447528 | G18: 3849604 | H18: =C18-G18 -> -1393 | I18: =IF(G18<>0,H18/G18,0) -> -0.0003618554 | J18: =IF(I18>=0.03,"🟢",IF(I18>=-0.03,"🟡","🔴")) -> 🟡 | K18: =ROUND(C18*0.05,0) -> 192411 | L18: =ROUND(D18*0.03,0) -> 71060 | M18: =E18-K18+L18 -> 1358191
A19: GESAMT 2015 / TOTAL 2015 | C19: =SUM(C7:C18) -> 20023991 | D19: =SUM(D7:D18) -> 12495428 | E19: =C19-D19 -> 7528563 | F19: =IF(C19<>0,E19/C19,0) -> 0.37597715 | G19: =SUM(G7:G18) -> 20012324 | H19: =C19-G19 -> 11667 | I19: =IF(G19<>0,H19/G19,0) -> 0.00058299076 | J19: =IF(I19>=0.03,"🟢",IF(I19>=-0.03,"🟡","🔴")) -> 🟡 | K19: =SUM(K7:K18) -> 1001199 | L19: =SUM(L7:L18) -> 374861 | M19: =SUM(M7:M18) -> 6902225
A21: Farbcode / Color Code: 🔵 Blau = Hardcodierte Eingaben (aus Rohdaten/Notebook) / Blue = Hardcoded inputs from raw data 🟢 Grün = Formeln (innerhalb dieses Sheets) / Green = Formulas within sheet 🟡 Gelb = Summenzeilen / Yellow = Total rows | ARAP = Aktive Rechnungsabgrenzung (Prepaid) PRAP = Passive Rechnungsabgrenzung (Deferred)

Sheet 📋 Annual Closing
A1: JAHRESABSCHLUSS / ANNUAL CLOSING STATEMENT — RetailCo 2011–2016
A2: Bruttomarge = Bruttoergebnis / Umsatz | Wachstum = YoY-Veränderung | Alle Beträge in USD
A4: FORMELN / FORMULAS
A5: Bruttoergebnis / GP | B5: Formel: =umsatz − COGS → =C{r}−D{r} | D5: Bruttomarge % | E5: Formel: =bruttoergebnis / umsatz → =E{r}/C{r} | G5: Umsatz-Plan-Abw.abs | H5: Formel: =umsatz_ist − Budget → =C{r}−G{r}
A6: Umsatz-Plan-Abw.% | B6: Formel: =(ist−Plan)/Plan → =H{r}/G{r}) | D6: YoY Wachstum Umsatz | E6: =(umsatz_t − Umsatz_{t-1}) / Umsatz_{t-1} → =(C{r}−C{r-1})/C{r-1})) | G6: YoY Wachstum Ergebnis | H6: =analog zu umsatz-wachstum → =(E{r}−E{r-1})/E{r-1}
A7: # | B7: GJ/FY | C7: Umsatz (Revenue) | D7: COGS (Costs) | E7: Bruttoergebnis (Gross Profit) | F7: Brutto- marge % | G7: Plan (Budget) | H7: Plan-Abw.abs (Var.abs) | I7: Plan-Abw.% (Var.%) | J7: YoY Umsatz Wachstum % | K7: YoY Ergebnis Wachstum %
A8: 1 | B8: 2011 | C8: 8964888 | D8: 6083587 | E8: =C8-D8 -> 2881301 | F8: =IF(C8<>0,E8/C8,0) -> 0.32139844 | G8: 8985125 | H8: =C8-G8 -> -20237 | I8: =IF(G8<>0,H8/G8,0) -> -0.0022522781 | J8: Basisjahr / Base | K8: Basisjahr / Base
A9: 2 | B9: 2012 | C9: 9175983 | D9: 6223990 | E9: =C9-D9 -> 2951993 | F9: =IF(C9<>0,E9/C9,0) -> 0.32170864 | G9: 9184327 | H9: =C9-G9 -> -8344 | I9: =IF(G9<>0,H9/G9,0) -> -0.00090850424 | J9: =IF(C8<>0,(C9-C8)/C8,0) -> 0.023546864 | K9: =IF(E8<>0,(E9-E8)/E8,0) -> 0.02453475
A10: 3 | B10: 2013 | C10: 15240037 | D10: 9280829 | E10: =C10-D10 -> 5959208 | F10: =IF(C10<>0,E10/C10,0) -> 0.3910232 | G10: 15249299 | H10: =C10-G10 -> -9262 | I10: =IF(G10<>0,H10/G10,0) -> -0.00060737218 | J10: =IF(C9<>0,(C10-C9)/C9,0) -> 0.66086151 | K10: =IF(E9<>0,(E10-E9)/E9,0) -> 1.0187067
A11: 4 | B11: 2014 | C11: 14152724 | D11: 8288637 | E11: =C11-D11 -> 5864087 | F11: =IF(C11<>0,E11/C11,0) -> 0.41434334 | G11: 14160768 | H11: =C11-G11 -> -8044 | I11: =IF(G11<>0,H11/G11,0) -> -0.00056804829 | J11: =IF(C10<>0,(C11-C10)/C10,0) -> -0.071345824 | K11: =IF(E10<>0,(E11-E10)/E10,0) -> -0.01596202
A12: 5 | B12: 2015 | C12: 20023991 | D12: 12495428 | E12: =C12-D12 -> 7528563 | F12: =IF(C12<>0,E12/C12,0) -> 0.37597715 | G12: 20012324 | H12: =C12-G12 -> 11667 | I12: =IF(G12<>0,H12/G12,0) -> 0.00058299076 | J12: =IF(C11<>0,(C12-C11)/C11,0) -> 0.41485067 | K12: =IF(E11<>0,(E12-E11)/E11,0) -> 0.28384231
A13: 6 | B13: 2016 | C13: 17713385 | D13: 10677437 | E13: =C13-D13 -> 7035948 | F13: =IF(C13<>0,E13/C13,0) -> 0.39721081 | G13: 17724314 | H13: =C13-G13 -> -10929 | I13: =IF(G13<>0,H13/G13,0) -> -0.00061661061 | J13: =IF(C12<>0,(C13-C12)/C12,0) -> -0.11539188 | K13: =IF(E12<>0,(E13-E12)/E12,0) -> -0.065432806
B14: GESAMT / TOTAL | C14: =SUM(C8:C13) -> 85271008 | D14: =SUM(D8:D13) -> 53049908 | E14: =C14-D14 -> 32221100 | F14: =IF(C14<>0,E14/C14,0) -> 0.377867 | G14: =SUM(G8:G13) -> 85316157 | H14: =C14-G14 -> -45149 | I14: =IF(G14<>0,H14/G14,0) -> -0.00052919636 | J14: — | K14: —

Sheet 📐 Accruals (ARAP-PRAP)
A1: RECHNUNGSABGRENZUNGSPOSTEN / ACCRUALS & DEFERRALS — 2015
A3: WAS IST RECHNUNGSABGRENZUNG? / WHAT IS ACCRUAL ACCOUNTING?
A4: DE: Rechnungsabgrenzungsposten stellen sicher, dass Erträge und Aufwendungen der richtigen Periode zugeordnet werden (Periodenabgrenzungsprinzip nach HGB/IFRS). Einnahmen oder Ausgaben, die periodenübergreifend wirken, werden aufgeteilt.
A5: EN: Accruals ensure revenues and expenses are recorded in the period they occur, not when cash changes hands (matching principle). This creates a more accurate picture of financial performance.
A6: ANNAHMEN / ASSUMPTIONS (Eingabe / Input)
A7: ARAP-Rate (Prepaid Revenue): | B7: 0.05 | C7: 5% des Umsatzes wird im Folgemonat fakturiert / 5% of revenue billed next month → Aktive Rechnungsabgrenzung (ARAP) / Asset on balance sheet | F7: PRAP-Rate (Deferred Cost): | G7: 0.03 | H7: 3% der Kosten betreffen Folgeperiode / 3% of costs belong to next period → Passive Rechnungsabgrenzung (PRAP) / Liability on balance sheet
A8: # | B8: Periode /Period | C8: Umsatz_Ist (Revenue) | D8: COGS_Ist (Costs) | E8: Ergebnis_Ist (Gross Profit) | F8: ARAP =Umsatz×B7 | G8: PRAP =COGS×G7 | H8: Ergebnis_bereinigt =GP−ARAP+PRAP | I8: ARAP-Erläuterung /Explanation | J8: PRAP-Erläuterung /Explanation
A9: 1 | B9: 2015-01 | C9: 666938 | D9: 447744 | E9: =C9-D9 -> 219194 | F9: =ROUND(C9*$B$7,0) -> 33347 | G9: =ROUND(D9*$G$7,0) -> 13432 | H9: =E9-F9+G9 -> 199279 | I9: ARAP = 666,938 × 5% = Umsatz wird im Folgemonat fakturiert / revenue billed next month → Aktivseite Bilanz / Balance sheet asset | J9: PRAP = 447,744 × 3% = Kosten betreffen Folgeperiode / costs belong to next period → Passivseite Bilanz / Balance sheet liability
A10: 2 | B10: 2015-02 | C10: 679246 | D10: 458635 | E10: =C10-D10 -> 220611 | F10: =ROUND(C10*$B$7,0) -> 33962 | G10: =ROUND(D10*$G$7,0) -> 13759 | H10: =E10-F10+G10 -> 200408 | I10: ARAP = 679,246 × 5% = Umsatz wird im Folgemonat fakturiert / revenue billed next month → Aktivseite Bilanz / Balance sheet asset | J10: PRAP = 458,635 × 3% = Kosten betreffen Folgeperiode / costs belong to next period → Passivseite Bilanz / Balance sheet liability
A11: 3 | B11: 2015-03 | C11: 714008 | D11: 477922 | E11: =C11-D11 -> 236086 | F11: =ROUND(C11*$B$7,0) -> 35700 | G11: =ROUND(D11*$G$7,0) -> 14338 | H11: =E11-F11+G11 -> 214724 | I11: ARAP = 714,008 × 5% = Umsatz wird im Folgemonat fakturiert / revenue billed next month → Aktivseite Bilanz / Balance sheet asset | J11: PRAP = 477,922 × 3% = Kosten betreffen Folgeperiode / costs belong to next period → Passivseite Bilanz / Balance sheet liability
A12: 4 | B12: 2015-04 | C12: 734608 | D12: 497020 | E12: =C12-D12 -> 237588 | F12: =ROUND(C12*$B$7,0) -> 36730 | G12: =ROUND(D12*$G$7,0) -> 14911 | H12: =E12-F12+G12 -> 215769 | I12: ARAP = 734,608 × 5% = Umsatz wird im Folgemonat fakturiert / revenue billed next month → Aktivseite Bilanz / Balance sheet asset | J12: PRAP = 497,020 × 3% = Kosten betreffen Folgeperiode / costs belong to next period → Passivseite Bilanz / Balance sheet liability
A13: 5 | B13: 2015-05 | C13: 895043 | D13: 597749 | E13: =C13-D13 -> 297294 | F13: =ROUND(C13*$B$7,0) -> 44752 | G13: =ROUND(D13*$G$7,0) -> 17932 | H13: =E13-F13+G13 -> 270474 | I13: ARAP = 895,043 × 5% = Umsatz wird im Folgemonat fakturiert / revenue billed next month → Aktivseite Bilanz / Balance sheet asset | J13: PRAP = 597,749 × 3% = Kosten betreffen Folgeperiode / costs belong to next period → Passivseite Bilanz / Balance sheet liability
A14: 6 | B14: 2015-06 | C14: 786480 | D14: 527616 | E14: =C14-D14 -> 258864 | F14: =ROUND(C14*$B$7,0) -> 39324 | G14: =ROUND(D14*$G$7,0) -> 15828 | H14: =E14-F14+G14 -> 235368 | I14: ARAP = 786,480 × 5% = Umsatz wird im Folgemonat fakturiert / revenue billed next month → Aktivseite Bilanz / Balance sheet asset | J14: PRAP = 527,616 × 3% = Kosten betreffen Folgeperiode / costs belong to next period → Passivseite Bilanz / Balance sheet liability
A15: 7 | B15: 2015-07 | C15: 1728398 | D15: 1118446 | E15: =C15-D15 -> 609952 | F15: =ROUND(C15*$B$7,0) -> 86420 | G15: =ROUND(D15*$G$7,0) -> 33553 | H15: =E15-F15+G15 -> 557085 | I15: ARAP = 1,728,398 × 5% = Umsatz wird im Folgemonat fakturiert / revenue billed next month → Aktivseite Bilanz / Balance sheet asset | J15: PRAP = 1,118,446 × 3% = Kosten betreffen Folgeperiode / costs belong to next period → Passivseite Bilanz / Balance sheet liability
A16: 8 | B16: 2015-08 | C16: 2140581 | D16: 1264046 | E16: =C16-D16 -> 876535 | F16: =ROUND(C16*$B$7,0) -> 107029 | G16: =ROUND(D16*$G$7,0) -> 37921 | H16: =E16-F16+G16 -> 807427 | I16: ARAP = 2,140,581 × 5% = Umsatz wird im Folgemonat fakturiert / revenue billed next month → Aktivseite Bilanz / Balance sheet asset | J16: PRAP = 1,264,046 × 3% = Kosten betreffen Folgeperiode / costs belong to next period → Passivseite Bilanz / Balance sheet liability
A17: 9 | B17: 2015-09 | C17: 2465172 | D17: 1478781 | E17: =C17-D17 -> 986391 | F17: =ROUND(C17*$B$7,0) -> 123259 | G17: =ROUND(D17*$G$7,0) -> 44363 | H17: =E17-F17+G17 -> 907495 | I17: ARAP = 2,465,172 × 5% = Umsatz wird im Folgemonat fakturiert / revenue billed next month → Aktivseite Bilanz / Balance sheet asset | J17: PRAP = 1,478,781 × 3% = Kosten betreffen Folgeperiode / costs belong to next period → Passivseite Bilanz / Balance sheet liability
A18: 10 | B18: 2015-10 | C18: 2529084 | D18: 1528465 | E18: =C18-D18 -> 1000619 | F18: =ROUND(C18*$B$7,0) -> 126454 | G18: =ROUND(D18*$G$7,0) -> 45854 | H18: =E18-F18+G18 -> 920019 | I18: ARAP = 2,529,084 × 5% = Umsatz wird im Folgemonat fakturiert / revenue billed next month → Aktivseite Bilanz / Balance sheet asset | J18: PRAP = 1,528,465 × 3% = Kosten betreffen Folgeperiode / costs belong to next period → Passivseite Bilanz / Balance sheet liability
A19: 11 | B19: 2015-11 | C19: 2836222 | D19: 1730335 | E19: =C19-D19 -> 1105887 | F19: =ROUND(C19*$B$7,0) -> 141811 | G19: =ROUND(D19*$G$7,0) -> 51910 | H19: =E19-F19+G19 -> 1015986 | I19: ARAP = 2,836,222 × 5% = Umsatz wird im Folgemonat fakturiert / revenue billed next month → Aktivseite Bilanz / Balance sheet asset | J19: PRAP = 1,730,335 × 3% = Kosten betreffen Folgeperiode / costs belong to next period → Passivseite Bilanz / Balance sheet liability
A20: 12 | B20: 2015-12 | C20: 3848211 | D20: 2368669 | E20: =C20-D20 -> 1479542 | F20: =ROUND(C20*$B$7,0) -> 192411 | G20: =ROUND(D20*$G$7,0) -> 71060 | H20: =E20-F20+G20 -> 1358191 | I20: ARAP = 3,848,211 × 5% = Umsatz wird im Folgemonat fakturiert / revenue billed next month → Aktivseite Bilanz / Balance sheet asset | J20: PRAP = 2,368,669 × 3% = Kosten betreffen Folgeperiode / costs belong to next period → Passivseite Bilanz / Balance sheet liability
A21: GESAMT / TOTAL 2015 | C21: =SUM(C9:C20) -> 20023991 | D21: =SUM(D9:D20) -> 12495428 | E21: =C21-D21 -> 7528563 | F21: =SUM(F9:F20) -> 1001199 | G21: =SUM(G9:G20) -> 374861 | H21: =SUM(H9:H20) -> 6902225
A23: BUCHUNGSSÄTZE / ACCOUNTING ENTRIES (Simulation / HGB-Logik)
A24: ARAP (Aktiv) | B24: Soll / Debit | C24: Aktive Rechnungsabgrenzung (ARAP) | D24: an / Credit | E24: Umsatzerlöse | F24: Formel: =5% des umsatzes wird auf die nächste periode verschoben. ergebnis sinkt / revenue deferred to next period → profit decreases
A25: PRAP (Passiv) | B25: Soll / Debit | C25: Aufwand (COGS) | D25: an / Credit | E25: Passive Rechnungsabgrenzung (PRAP) | F25: Formel: =3% der kosten betreffen die nächste periode. aufwand dieser periode sinkt / cost deferred → current period expense decreases

Sheet 📖 Legende & Formeln
A1: LEGENDE, FARBCODES & FORMELREFERENZ / LEGEND, COLOR CODES & FORMULA REFERENCE
A3: FARBCODES / COLOR CODES
A4: 🔵 Blau / Blue text | B4: Hardcodierte Eingaben aus Rohdaten (CSV) oder Notebook / Hardcoded inputs from raw data or notebook
A5: 🟢 Grüner Text / Green text | B5: Formeln, die innerhalb des gleichen Sheets berechnet werden / Formulas calculated within same sheet
A6: 🔴 Roter Text / Red text | B6: Externe Verknüpfungen (andere Dateien) / External links to other files
A7: 🟡 Gelber Hintergrund / Yellow bg | B7: Summenzeilen und Ergebniszellen / Total rows and result cells
A8: 🔵 Hellblauer Hintergrund / Light blue bg | B8: Eingabezellen (änderbar) / Input cells (editable)
A9: ⬜ Weiß / White bg | B9: Formelzellen / Formula cells
A10: 🩶 Grau / Grey bg | B10: Alternierende Datenzeilen / Alternating data rows
A12: ABKÜRZUNGEN / ABBREVIATIONS
A13: GuV / P&L | B13: Gewinn- und Verlustrechnung / Profit & Loss Statement
A14: COGS | B14: Cost of Goods Sold = Umsatzkosten / Cost of revenue
A15: GP / Bruttoergebnis | B15: Gross Profit = Umsatz − COGS
A16: GM% / Bruttomarge % | B16: Gross Margin % = GP / Umsatz (Revenue)
A17: ARAP | B17: Aktive Rechnungsabgrenzung / Prepaid revenue (asset): 5% × Umsatz
A18: PRAP | B18: Passive Rechnungsabgrenzung / Deferred cost (liability): 3% × COGS
A19: Abw. / Var. | B19: Abweichung / Variance = Ist − Plan
A20: RAG | B20: Red-Amber-Green Status: Rot <−3% | Amber ±3% | Grün >+3%
A21: WD | B21: Working Day / Arbeitstag (WD-3 = 3 Tage vor Abschluss)
A22: YoY | B22: Year over Year = Jahresvergleich
A23: GJ / FY | B23: Geschäftsjahr / Fiscal Year
A25: SCHLÜSSELFORMELN / KEY FORMULAS
A26: Bruttoergebnis / Gross Profit | B26: Formel: =umsatz_ist − COGS_Ist | =C{r}−D{r}
A27: Bruttomarge % / Gross Margin | B27: Formel: =gp / umsatz | =e{r}/c{r} | format: 0%
A28: Abweichung absolut / Var.abs | B28: Formel: =ist − Plan | =C{r}−G{r} | Positiv = über Plan
A29: Abweichung % / Var.% | B29: Formel: =(ist − Plan) / Plan | =H{r}/G{r} | Format: 0.0%)
A30: ARAP | B30: Formel: =ROUND(umsatz × $B$7, 0) | Rate in Annahmen-Zelle / rate in assumption cell,0)
A31: PRAP | B31: Formel: =ROUND(cogs × $G$7, 0) | Rate in Annahmen-Zelle / rate in assumption cell,0)
A32: Bereinigtes Ergebnis / Adj.Result | B32: Formel: =gp − ARAP + PRAP | =E{r}−F{r}+G{r}
A33: RAG Status | B33: Formel: =IF(var%>=3%,"🟢",IF(var%>=-3%,"🟡","🔴"))
A34: YoY Wachstum / YoY Growth | B34: Formel: =(wert_t − Wert_{t-1}) / Wert_{t-1} | =(C{r}−C{r-1})/C{r-1})
A35: Jahressumme / Annual Sum | B35: Formel: =SUM(monatszeilen) / =SUM(monthly rows)
A37: DATENQUELLEN / DATA SOURCES
A38: bike_sales_clean.csv | B38: Vorbereitete Rohdaten aus Modul 0 / Prepared raw data from Module 0
A39: revenue / Umsatz_Ist | B39: df['revenue'] — tatsächliche Verkaufserlöse pro Transaktion
A40: cost / COGS_Ist | B40: df['cost'] — tatsächliche Kosten pro Transaktion
A41: profit / Ergebnis_Ist | B41: df['profit'] = revenue − cost (berechnet in Rohdaten)
A42: revenue_plan / Plan | B42: df['revenue_plan'] — Planwerte aus Rohdaten
A43: fiscal_year / GJ | B43: df['fiscal_year'] — Geschäftsjahr (Kalender = Geschäftsjahr)
A44: year_month / Periode | B44: df['date'].dt.to_period('M') — z.B. 2015-01
...

Sheet 🗃️ Raw Data (Sample)
A1: 🗃️ ROHDATEN (STICHPROBE) / RAW DATA (SAMPLE) — 2015 | 300 Transaktionen
A2: DE: Jede Zeile = 1 Transaktion aus dem Datensatz. Profit = Excel-Formel (Revenue−Cost). | EN: Each row = 1 transaction. Profit = Excel formula (Revenue−Cost).
A3: 🔵 Blau/Blue = Rohdaten-Eingabe (hardcoded) | 🟢 Grün/Green = Excel-Formel / Excel formula | Profit-Spalte = Revenue−Cost
A4: Datum/Date | B4: Land EN/Country | C4: Land DE | D4: Kategorie/Category | E4: Unterkategorie/Subcat. | F4: Menge/Qty | G4: Stückkosten/Unit Cost | H4: Stückpreis/Unit Price | I4: Kosten/COGS | J4: Umsatz/Revenue | K4: Gewinn/Profit
A5: 42005 | B5: United States | C5: Vereinigte Staaten | D5: Bikes | E5: Road Bikes | F5: 3 | G5: 2171 | H5: 3578 | I5: 6513 | J5: 8373 | K5: =J5-I5 -> 1860
A6: 42005 | B6: Germany | C6: Deutschland | D6: Bikes | E6: Road Bikes | F6: 1 | G6: 1555 | H6: 2443 | I6: 1555 | J6: 2272 | K6: =J6-I6 -> 717
A7: 42005 | B7: United States | C7: Vereinigte Staaten | D7: Bikes | E7: Mountain Bikes | F7: 1 | G7: 1266 | H7: 2320 | I7: 1266 | J7: 2274 | K7: =J7-I7 -> 1008
A8: 42005 | B8: United States | C8: Vereinigte Staaten | D8: Bikes | E8: Road Bikes | F8: 1 | G8: 487 | H8: 783 | I8: 487 | J8: 673 | K8: =J8-I8 -> 186
A9: 42005 | B9: Australia | C9: Australien | D9: Bikes | E9: Road Bikes | F9: 1 | G9: 1083 | H9: 1701 | I9: 1083 | J9: 1429 | K9: =J9-I9 -> 346
A10: 42005 | B10: France | C10: Frankreich | D10: Bikes | E10: Road Bikes | F10: 1 | G10: 1555 | H10: 2443 | I10: 1555 | J10: 2003 | K10: =J10-I10 -> 448
A11: 42005 | B11: United States | C11: Vereinigte Staaten | D11: Bikes | E11: Road Bikes | F11: 3 | G11: 487 | H11: 783 | I11: 1461 | J11: 2232 | K11: =J11-I11 -> 771
A12: 42005 | B12: Australia | C12: Australien | D12: Bikes | E12: Road Bikes | F12: 1 | G12: 713 | H12: 1120 | I12: 713 | J12: 974 | K12: =J12-I12 -> 261
A13: 42006 | B13: Australia | C13: Australien | D13: Bikes | E13: Road Bikes | F13: 2 | G13: 2171 | H13: 3578 | I13: 4342 | J13: 6226 | K13: =J13-I13 -> 1884
A14: 42006 | B14: France | C14: Frankreich | D14: Bikes | E14: Road Bikes | F14: 1 | G14: 2171 | H14: 3578 | I14: 2171 | J14: 3435 | K14: =J14-I14 -> 1264
A15: 42006 | B15: United Kingdom | C15: Vereinigtes Königreich | D15: Bikes | E15: Road Bikes | F15: 2 | G15: 1083 | H15: 1701 | I15: 2166 | J15: 3266 | K15: =J15-I15 -> 1100
A16: 42006 | B16: United States | C16: Vereinigte Staaten | D16: Bikes | E16: Road Bikes | F16: 1 | G16: 2171 | H16: 3578 | I16: 2171 | J16: 3506 | K16: =J16-I16 -> 1335
... A304: 42041 | B304: United States | C304: Vereinigte Staaten | D304: Bikes | E304: Mountain Bikes | F304: 1 | G304: 1266 | H304: 2320 | I304: 1266 | J304: 1810 | K304: =J304-I304 -> 544
A305: SUMME (300 Transaktionen) / TOTAL | I305: =SUM(I5:I304) -> 534235 | J305: =SUM(J5:J304) -> 795005 | K305: =SUM(K5:K304) -> 260770
A307: ℹ️ Stichprobe: 300 von 20.178 Transaktionen (2015). Python verarbeitet alle 113.036 Zeilen. Das nächste Sheet zeigt dieselben Berechnungen mit Excel-SUMIFS-Formeln. / Sample: 300 of 20,178 transactions (2015). Python processes all 113,036 rows. Next sheet shows the same calculations using Excel SUMIFS formulas.

Sheet 🧮 Excel Calculations
A1: 🧮 EXCEL-BERECHNUNGEN / EXCEL CALCULATIONS — Python vs. Excel Vergleich / Comparison
A2: DE: Alle Berechnungen direkt in Excel mit SUMIFS — kein Python nötig. SUMIFS = summiert Werte wenn mehrere Bedingungen zutreffen (Monat + Jahr). | EN: All calculations done in Excel using SUMIFS — no Python needed. SUMIFS = sums values when multiple conditions are met (month + year).
A4: ① ANNAHMEN / ASSUMPTIONS — Gelbe Zellen änderbar / Yellow cells are editable inputs
B5: Geschäftsjahr / Fiscal Year | C5: 2015 | D5: Filtert alle SUMIFS-Formeln / Filters all SUMIFS formulas
B6: ARAP-Rate (Aktive Rechnungsabgr.) | C6: 0.05 | D6: 5% Umsatz → Aktiver Rechnungsabgrenzungsposten / 5% revenue → prepaid asset
B7: PRAP-Rate (Passive Rechnungsabgr.) | C7: 0.03 | D7: 3% Kosten → Passiver Rechnungsabgrenzungsposten / 3% cost → deferred liability
B8: Materialitätsschwelle / Materiality | C8: 0.05 | D8: Abw. ≥5% → Kommentarpflicht im Abschluss / Variance ≥5% → commentary required
B9: RAG Grün-Schwelle / Green threshold | C9: 0.03 | D9: ≥+3% Abweichung = 🟢 Grün/Green — über Plan / above budget
B10: RAG Rot-Schwelle / Red threshold | C10: -0.03 | D10: ≤−3% Abweichung = 🔴 Rot/Red — unter Plan / below budget
A12: ② FORMELERKLÄRUNG / FORMULA EXPLANATION — 🟢 Grün = Formel / Green = formula | 🔵 Blau = Eingabe / Blue = input
B13: SUMIFS — Umsatz/Revenue | C13: Beispiel / Example: SUMIFS(Revenue-Spalte, Datum-Spalte, ">="&Monatsanfang, Datum-Spalte, "<"&Monatsende) | H13: DE: Summiert Revenue (Spalte J) wo Datum ≥ Monatsanfang UND < nächster Monatsanfang. EN: Sums Revenue (col J) where date ≥ month start AND < next month start. SUMIFS = SUMMEWENNS auf Deutsch.
B14: Bruttoergebnis / Gross Profit | C14: Beispiel / Example: Umsatz − Kosten → =D25-E25 | H14: DE: Umsatz (D) minus Kosten (E) = Bruttoergebnis. Direkte Subtraktion. EN: Revenue (D) minus COGS (E) = Gross Profit. Direct subtraction.
B15: Bruttomarge % / Gross Margin % | C15: Beispiel / Example: WENN/IF(Umsatz>0, Bruttoergebnis/Umsatz, 0) → =IF(D25>0,F25/D25,0) | H15: DE: Bruttoergebnis / Umsatz. IF schützt vor Division durch Null. EN: Gross Profit / Revenue. IF protects against division by zero.
B16: ARAP (Aktive Rechnungsabgrenzung) | C16: Beispiel / Example: RUNDEN/ROUND(Umsatz × ARAP-Rate, 0) → =ROUND(D25*$C$6,0) | H16: DE: 5% des Umsatzes (Rate aus Annahmen-Zelle C6 — absoluter Bezug mit $). EN: 5% of Revenue (rate from assumption cell C6 — absolute reference with $).
B17: PRAP (Passive Rechnungsabgrenzung) | C17: Beispiel / Example: RUNDEN/ROUND(Kosten × PRAP-Rate, 0) → =ROUND(E25*$C$7,0) | H17: DE: 3% der Kosten (Rate aus C7). ROUND rundet auf ganze Zahlen. EN: 3% of COGS (rate from C7). ROUND to whole numbers.
B18: Bereinigtes Ergebnis / Adjusted Result | C18: Beispiel / Example: Bruttoergebnis − ARAP + PRAP → =F25-H25+I25 | H18: DE: Bruttoergebnis − ARAP + PRAP = periodenbereinigtes Ergebnis nach HGB. EN: Gross Profit − ARAP + PRAP = period-adjusted result per HGB/IFRS.
B19: Abweichung abs / Variance abs | C19: Beispiel / Example: Umsatz_Ist − Umsatz_Plan → =D25-K25 | H19: DE: Ist minus Plan. Positiv = über Plan (favorable). Negativ = unter Plan (adverse). EN: Actual minus Budget. Positive = above plan (favorable). Negative = below plan (adverse).
B20: Abweichung % / Variance % | C20: Beispiel / Example: WENN/IF(Plan>0, Abw_abs/Plan, 0) → =IF(K25>0,L25/K25,0) | H20: DE: Absolute Abweichung geteilt durch Plan = relative Abweichung in %. EN: Absolute variance divided by Budget = relative variance %.
B21: RAG Status | C21: Beispiel / Example: WENN/IF(Abw%>=Grün_Schwelle, Grün, WENN(Abw%>Rot_Schwelle, Amber, Rot)) | H21: DE: Verschachtelte IF-Formel. Prüft Abw.% gegen Grün/Rot-Schwelle aus Annahmen. EN: Nested IF formula. Checks var% against Green/Red threshold from assumptions.
A23: ③ MONATLICHE GuV VIA SUMIFS / MONTHLY P&L VIA SUMIFS 2015 — Formeln referenzieren Sheet "🗃️ Raw Data" / Formulas reference sheet "🗃️ Raw Data"
A24: # | B24: Periode /Period | C24: Monat /Month | D24: Umsatz_Ist /Revenue (SUMIFS) | E24: Kosten_Ist /COGS (SUMIFS) | F24: Bruttoerg. /Gross Profit (=D−E) | G24: Marge% (=F/D) | H24: ARAP (=D×Rate) | I24: PRAP (=E×Rate) | J24: Ber.Erg. /Adj.Result (=F−H+I) | K24: Plan/Budget (hardcoded) | L24: Abw.abs /Var.abs (=D−K) | M24: RAG
A25: 1 | B25: 2015-01 | C25: 1 | D25: =SUMIFS('🗃️ Raw Data (Sample)'!J:J,'🗃️ Raw Data (Sample)'!A:A,">="&DATE($C$5,1,1),'🗃️ Raw Data (Sample)'!A:A,"<"&DATE($C$5,1+1,1)) -> 666938 | E25: =SUMIFS('🗃️ Raw Data (Sample)'!I:I,'🗃️ Raw Data (Sample)'!A:A,">="&DATE($C$5,1,1),'🗃️ Raw Data (Sample)'!A:A,"<"&DATE($C$5,1+1,1)) -> 447744 | F25: =D25-E25 -> 219194 | G25: =IF(D25>0,F25/D25,0) -> 0.32865724 | H25: =ROUND(D25*$C$6,0) -> 33347 | I25: =ROUND(E25*$C$7,0) -> 13432 | J25: =F25-H25+I25 -> 199279 | K25: 665780 | L25: =D25-K25 -> 1158 | M25: =IF(L25>=$C$9,"🟢 Grün",IF(L25>$C$10,"🟡 Amber","🔴 Rot")) -> 🟢 Grün
A26: 2 | B26: 2015-02 | C26: 2 | D26: =SUMIFS('🗃️ Raw Data (Sample)'!J:J,'🗃️ Raw Data (Sample)'!A:A,">="&DATE($C$5,2,1),'🗃️ Raw Data (Sample)'!A:A,"<"&DATE($C$5,2+1,1)) -> 128067 | E26: =SUMIFS('🗃️ Raw Data (Sample)'!I:I,'🗃️ Raw Data (Sample)'!A:A,">="&DATE($C$5,2,1),'🗃️ Raw Data (Sample)'!A:A,"<"&DATE($C$5,2+1,1)) -> 86491 | F26: =D26-E26 -> 41576 | G26: =IF(D26>0,F26/D26,0) -> 0.32464257 | H26: =ROUND(D26*$C$6,0) -> 6403 | I26: =ROUND(E26*$C$7,0) -> 2595 | J26: =F26-H26+I26 -> 37768 | K26: 672878 | L26: =D26-K26 -> -544811 | M26: =IF(L26>=$C$9,"🟢 Grün",IF(L26>$C$10,"🟡 Amber","🔴 Rot")) -> 🔴 Rot
A27: 3 | B27: 2015-03 | C27: 3 | D27: =SUMIFS('🗃️ Raw Data (Sample)'!J:J,'🗃️ Raw Data (Sample)'!A:A,">="&DATE($C$5,3,1),'🗃️ Raw Data (Sample)'!A:A,"<"&DATE($C$5,3+1,1)) -> 0 | E27: =SUMIFS('🗃️ Raw Data (Sample)'!I:I,'🗃️ Raw Data (Sample)'!A:A,">="&DATE($C$5,3,1),'🗃️ Raw Data (Sample)'!A:A,"<"&DATE($C$5,3+1,1)) -> 0 | F27: =D27-E27 -> 0 | G27: =IF(D27>0,F27/D27,0) -> 0 | H27: =ROUND(D27*$C$6,0) -> 0 | I27: =ROUND(E27*$C$7,0) -> 0 | J27: =F27-H27+I27 -> 0 | K27: 712079 | L27: =D27-K27 -> -712079 | M27: =IF(L27>=$C$9,"🟢 Grün",IF(L27>$C$10,"🟡 Amber","🔴 Rot")) -> 🔴 Rot
A28: 4 | B28: 2015-04 | C28: 4 | D28: =SUMIFS('🗃️ Raw Data (Sample)'!J:J,'🗃️ Raw Data (Sample)'!A:A,">="&DATE($C$5,4,1),'🗃️ Raw Data (Sample)'!A:A,"<"&DATE($C$5,4+1,1)) -> 0 | E28: =SUMIFS('🗃️ Raw Data (Sample)'!I:I,'🗃️ Raw Data (Sample)'!A:A,">="&DATE($C$5,4,1),'🗃️ Raw Data (Sample)'!A:A,"<"&DATE($C$5,4+1,1)) -> 0 | F28: =D28-E28 -> 0 | G28: =IF(D28>0,F28/D28,0) -> 0 | H28: =ROUND(D28*$C$6,0) -> 0 | I28: =ROUND(E28*$C$7,0) -> 0 | J28: =F28-H28+I28 -> 0 | K28: 728736 | L28: =D28-K28 -> -728736 | M28: =IF(L28>=$C$9,"🟢 Grün",IF(L28>$C$10,"🟡 Amber","🔴 Rot")) -> 🔴 Rot
A29: 5 | B29: 2015-05 | C29: 5 | D29: =SUMIFS('🗃️ Raw Data (Sample)'!J:J,'🗃️ Raw Data (Sample)'!A:A,">="&DATE($C$5,5,1),'🗃️ Raw Data (Sample)'!A:A,"<"&DATE($C$5,5+1,1)) -> 0 | E29: =SUMIFS('🗃️ Raw Data (Sample)'!I:I,'🗃️ Raw Data (Sample)'!A:A,">="&DATE($C$5,5,1),'🗃️ Raw Data (Sample)'!A:A,"<"&DATE($C$5,5+1,1)) -> 0 | F29: =D29-E29 -> 0 | G29: =IF(D29>0,F29/D29,0) -> 0 | H29: =ROUND(D29*$C$6,0) -> 0 | I29: =ROUND(E29*$C$7,0) -> 0 | J29: =F29-H29+I29 -> 0 | K29: 901206 | L29: =D29-K29 -> -901206 | M29: =IF(L29>=$C$9,"🟢 Grün",IF(L29>$C$10,"🟡 Amber","🔴 Rot")) -> 🔴 Rot
A30: 6 | B30: 2015-06 | C30: 6 | D30: =SUMIFS('🗃️ Raw Data (Sample)'!J:J,'🗃️ Raw Data (Sample)'!A:A,">="&DATE($C$5,6,1),'🗃️ Raw Data (Sample)'!A:A,"<"&DATE($C$5,6+1,1)) -> 0 | E30: =SUMIFS('🗃️ Raw Data (Sample)'!I:I,'🗃️ Raw Data (Sample)'!A:A,">="&DATE($C$5,6,1),'🗃️ Raw Data (Sample)'!A:A,"<"&DATE($C$5,6+1,1)) -> 0 | F30: =D30-E30 -> 0 | G30: =IF(D30>0,F30/D30,0) -> 0 | H30: =ROUND(D30*$C$6,0) -> 0 | I30: =ROUND(E30*$C$7,0) -> 0 | J30: =F30-H30+I30 -> 0 | K30: 786483 | L30: =D30-K30 -> -786483 | M30: =IF(L30>=$C$9,"🟢 Grün",IF(L30>$C$10,"🟡 Amber","🔴 Rot")) -> 🔴 Rot
A31: 7 | B31: 2015-07 | C31: 7 | D31: =SUMIFS('🗃️ Raw Data (Sample)'!J:J,'🗃️ Raw Data (Sample)'!A:A,">="&DATE($C$5,7,1),'🗃️ Raw Data (Sample)'!A:A,"<"&DATE($C$5,7+1,1)) -> 0 | E31: =SUMIFS('🗃️ Raw Data (Sample)'!I:I,'🗃️ Raw Data (Sample)'!A:A,">="&DATE($C$5,7,1),'🗃️ Raw Data (Sample)'!A:A,"<"&DATE($C$5,7+1,1)) -> 0 | F31: =D31-E31 -> 0 | G31: =IF(D31>0,F31/D31,0) -> 0 | H31: =ROUND(D31*$C$6,0) -> 0 | I31: =ROUND(E31*$C$7,0) -> 0 | J31: =F31-H31+I31 -> 0 | K31: 1721640 | L31: =D31-K31 -> -1721640 | M31: =IF(L31>=$C$9,"🟢 Grün",IF(L31>$C$10,"🟡 Amber","🔴 Rot")) -> 🔴 Rot
A32: 8 | B32: 2015-08 | C32: 8 | D32: =SUMIFS('🗃️ Raw Data (Sample)'!J:J,'🗃️ Raw Data (Sample)'!A:A,">="&DATE($C$5,8,1),'🗃️ Raw Data (Sample)'!A:A,"<"&DATE($C$5,8+1,1)) -> 0 | E32: =SUMIFS('🗃️ Raw Data (Sample)'!I:I,'🗃️ Raw Data (Sample)'!A:A,">="&DATE($C$5,8,1),'🗃️ Raw Data (Sample)'!A:A,"<"&DATE($C$5,8+1,1)) -> 0 | F32: =D32-E32 -> 0 | G32: =IF(D32>0,F32/D32,0) -> 0 | H32: =ROUND(D32*$C$6,0) -> 0 | I32: =ROUND(E32*$C$7,0) -> 0 | J32: =F32-H32+I32 -> 0 | K32: 2139961 | L32: =D32-K32 -> -2139961 | M32: =IF(L32>=$C$9,"🟢 Grün",IF(L32>$C$10,"🟡 Amber","🔴 Rot")) -> 🔴 Rot
A33: 9 | B33: 2015-09 | C33: 9 | D33: =SUMIFS('🗃️ Raw Data (Sample)'!J:J,'🗃️ Raw Data (Sample)'!A:A,">="&DATE($C$5,9,1),'🗃️ Raw Data (Sample)'!A:A,"<"&DATE($C$5,9+1,1)) -> 0 | E33: =SUMIFS('🗃️ Raw Data (Sample)'!I:I,'🗃️ Raw Data (Sample)'!A:A,">="&DATE($C$5,9,1),'🗃️ Raw Data (Sample)'!A:A,"<"&DATE($C$5,9+1,1)) -> 0 | F33: =D33-E33 -> 0 | G33: =IF(D33>0,F33/D33,0) -> 0 | H33: =ROUND(D33*$C$6,0) -> 0 | I33: =ROUND(E33*$C$7,0) -> 0 | J33: =F33-H33+I33 -> 0 | K33: 2459901 | L33: =D33-K33 -> -2459901 | M33: =IF(L33>=$C$9,"🟢 Grün",IF(L33>$C$10,"🟡 Amber","🔴 Rot")) -> 🔴 Rot
A34: 10 | B34: 2015-10 | C34: 10 | D34: =SUMIFS('🗃️ Raw Data (Sample)'!J:J,'🗃️ Raw Data (Sample)'!A:A,">="&DATE($C$5,10,1),'🗃️ Raw Data (Sample)'!A:A,"<"&DATE($C$5,10+1,1)) -> 0 | E34: =SUMIFS('🗃️ Raw Data (Sample)'!I:I,'🗃️ Raw Data (Sample)'!A:A,">="&DATE($C$5,10,1),'🗃️ Raw Data (Sample)'!A:A,"<"&DATE($C$5,10+1,1)) -> 0 | F34: =D34-E34 -> 0 | G34: =IF(D34>0,F34/D34,0) -> 0 | H34: =ROUND(D34*$C$6,0) -> 0 | I34: =ROUND(E34*$C$7,0) -> 0 | J34: =F34-H34+I34 -> 0 | K34: 2538826 | L34: =D34-K34 -> -2538826 | M34: =IF(L34>=$C$9,"🟢 Grün",IF(L34>$C$10,"🟡 Amber","🔴 Rot")) -> 🔴 Rot
A35: 11 | B35: 2015-11 | C35: 11 | D35: =SUMIFS('🗃️ Raw Data (Sample)'!J:J,'🗃️ Raw Data (Sample)'!A:A,">="&DATE($C$5,11,1),'🗃️ Raw Data (Sample)'!A:A,"<"&DATE($C$5,11+1,1)) -> 0 | E35: =SUMIFS('🗃️ Raw Data (Sample)'!I:I,'🗃️ Raw Data (Sample)'!A:A,">="&DATE($C$5,11,1),'🗃️ Raw Data (Sample)'!A:A,"<"&DATE($C$5,11+1,1)) -> 0 | F35: =D35-E35 -> 0 | G35: =IF(D35>0,F35/D35,0) -> 0 | H35: =ROUND(D35*$C$6,0) -> 0 | I35: =ROUND(E35*$C$7,0) -> 0 | J35: =F35-H35+I35 -> 0 | K35: 2835230 | L35: =D35-K35 -> -2835230 | M35: =IF(L35>=$C$9,"🟢 Grün",IF(L35>$C$10,"🟡 Amber","🔴 Rot")) -> 🔴 Rot
A36: 12 | B36: 2015-12 | C36: 12 | D36: =SUMIFS('🗃️ Raw Data (Sample)'!J:J,'🗃️ Raw Data (Sample)'!A:A,">="&DATE($C$5,12,1),'🗃️ Raw Data (Sample)'!A:A,"<"&DATE($C$5+1,1,1)) -> 0 | E36: =SUMIFS('🗃️ Raw Data (Sample)'!I:I,'🗃️ Raw Data (Sample)'!A:A,">="&DATE($C$5,12,1),'🗃️ Raw Data (Sample)'!A:A,"<"&DATE($C$5+1,1,1)) -> 0 | F36: =D36-E36 -> 0 | G36: =IF(D36>0,F36/D36,0) -> 0 | H36: =ROUND(D36*$C$6,0) -> 0 | I36: =ROUND(E36*$C$7,0) -> 0 | J36: =F36-H36+I36 -> 0 | K36: 3849604 | L36: =D36-K36 -> -3849604 | M36: =IF(L36>=$C$9,"🟢 Grün",IF(L36>$C$10,"🟡 Amber","🔴 Rot")) -> 🔴 Rot
A37: GESAMT 2015 / TOTAL 2015 | D37: =SUM(D25:D36) -> 795005 | E37: =SUM(E25:E36) -> 534235 | F37: =SUM(F25:F36) -> 260770 | G37: =IF(D37>0,F37/D37,0) -> 0.32801052 | H37: =SUM(I25:I36) -> 16027 | I37: =SUM(J25:J36) -> 237047 | J37: =SUM(K25:K36) -> 20012324 | K37: =SUM(L25:L36) -> -19217319
A39: ④ PYTHON vs. EXCEL — Wann was benutzen? / When to use which?
A40: Kriterium/Criterion | D40: Python (pandas) | G40: Excel (SUMIFS) | J40: Empfehlung/Recommendation
A41: Datenmenge / Data volume | D41: ✅ Ideal für >10k Zeilen (113k Zeilen in Sekunden) | H41: ⚠️ Langsam bei >100k Zeilen (Slow above 100k rows) | L41: → Python für große Rohdaten /for large raw data
A42: Transparenz / Transparency | D42: ⚠️ Code nötig / Code required (Nicht alle lesen Python) | H42: ✅ Jede Formel sichtbar (Every formula visible) | L42: → Excel für Management-Reports /for management reports
A43: Automatisierung / Automation | D43: ✅ Vollautomatisch, reproduzierbar (Fully automated, reproducible) | H43: ⚠️ Manuell aktualisieren (Manual update needed) | L43: → Python für Monatsreports /for recurring monthly reports
A44: Ergebnis / Result | D44: ✅ Gleich/Same: Revenue Jan = 52.904 | H44: ✅ Gleich/Same: Revenue Jan = SUMIFS | L44: 🎯 Beide Wege = gleiches Ergebnis /Both approaches = same result!

Sheet 📊 KPI Dashboard
A1: 📊 KPI-DASHBOARD / KPI OVERVIEW — Formeln aus Raw Data / Formulas from Raw Data
A2: DE: Alle Werte über SUMIFS aus "🗃️ Raw Data (Sample)" berechnet. Sample = 2015 (300 Transaktionen). | EN: All values calculated via SUMIFS from Raw Data. Sample = 2015 (300 transactions).
A3: 🔵 Blau/Blue = hardcoded Eingabe/input | 🟢 Grün/Green = Excel-Formel aus Raw Data / Excel formula from Raw Data | 🟡 Gelb/Yellow = Annahme änderbar / editable assumption | Formeln referenzieren: "🗃️ Raw Data (Sample)" / Formulas reference: "🗃️ Raw Data (Sample)"
A5: ① JAHRES-KPIS 2015 / ANNUAL KPIs 2015 — via SUMIFS aus/from Raw Data
A6: GJ/FY | B6: Umsatz /Revenue (SUMIFS) | C6: COGS /Costs (SUMIFS) | D6: Bruttoergebnis /Gross Profit (=B−C) | E6: Bruttomarge% /GM% (=D/B) | F6: Umsatz Plan /Budget (hardcoded) | G6: Plan-Abw.abs /Var.abs (=B−F) | H6: Plan-Abw.% /Var.% (=G/F) | I6: Bewertung /Assessment
A7: 2015 | B7: =SUMIFS('🗃️ Raw Data (Sample)'!J:J,'🗃️ Raw Data (Sample)'!A:A,">="&DATE(2015,1,1),'🗃️ Raw Data (Sample)'!A:A,"<"&DATE(2016,1,1)) -> 795005 | C7: =SUMIFS('🗃️ Raw Data (Sample)'!I:I,'🗃️ Raw Data (Sample)'!A:A,">="&DATE(2015,1,1),'🗃️ Raw Data (Sample)'!A:A,"<"&DATE(2016,1,1)) -> 534235 | D7: =B7-C7 -> 260770 | E7: =IF(B7>0,D7/B7,0) -> 0.32801052 | F7: 20012324 | G7: =B7-F7 -> -19217319 | H7: =IF(F7>0,G7/F7,0) -> -0.96027423 | I7: =IF(H7>=0.03,"🟢 Ziel erreicht / On target",IF(H7>=-0.03,"🟡 Im Rahmen / Within range","🔴 Unter Plan / Below budget")) -> 🔴 Unter Plan / Below budget
A9: ℹ️ Hinweis / Note: Das Raw Data Sample enthält nur 2015 (300 Transaktionen). Für alle Jahre 2011–2016 → siehe Sheet "📋 Annual Closing" (vollständige Daten via Python). Die SUMIFS-Logik ist identisch — einfach das Datenjahr in Spalte B ändern.
A11: ② KPI NACH KATEGORIE / BY CATEGORY 2015 — SUMIFS(Kategorie-Filter/Category filter)
A12: # | B12: Kategorie /Category | C12: Umsatz /Revenue (SUMIFS) | D12: COGS (SUMIFS) | E12: Bruttoergebnis /GP (=C−D) | F12: DB-Quote% /CM Rate% (=E/C) | G12: Rev Share% /Umsatzanteil% (=C/ΣC) | H12: Bewertung /Assessment | I12: Formel-Beispiel / Formula Example
A13: 1 | B13: Accessories | C13: =SUMIFS('🗃️ Raw Data (Sample)'!J:J,'🗃️ Raw Data (Sample)'!D:D,B13) -> 0 | D13: =SUMIFS('🗃️ Raw Data (Sample)'!I:I,'🗃️ Raw Data (Sample)'!D:D,B13) -> 0 | E13: =C13-D13 -> 0 | F13: =IF(C13>0,E13/C13,0) -> 0 | G13: =IF(C16>0,C13/C16,0) -> 0 | H13: =IF(F13>=0.5,"✅ Stark/Strong",IF(F13>=0.33,"⚠️ Mittel/Medium","❌ Schwach/Weak")) -> ❌ Schwach/Weak | I13: SUMIFS(Revenue, Category, "Accessories")
A14: 2 | B14: Bikes | C14: =SUMIFS('🗃️ Raw Data (Sample)'!J:J,'🗃️ Raw Data (Sample)'!D:D,B14) -> 795005 | D14: =SUMIFS('🗃️ Raw Data (Sample)'!I:I,'🗃️ Raw Data (Sample)'!D:D,B14) -> 534235 | E14: =C14-D14 -> 260770 | F14: =IF(C14>0,E14/C14,0) -> 0.32801052 | G14: =IF(C16>0,C14/C16,0) -> 1 | H14: =IF(F14>=0.5,"✅ Stark/Strong",IF(F14>=0.33,"⚠️ Mittel/Medium","❌ Schwach/Weak")) -> ❌ Schwach/Weak | I14: SUMIFS(Revenue, Category, "Bikes")
A15: 3 | B15: Clothing | C15: =SUMIFS('🗃️ Raw Data (Sample)'!J:J,'🗃️ Raw Data (Sample)'!D:D,B15) -> 0 | D15: =SUMIFS('🗃️ Raw Data (Sample)'!I:I,'🗃️ Raw Data (Sample)'!D:D,B15) -> 0 | E15: =C15-D15 -> 0 | F15: =IF(C15>0,E15/C15,0) -> 0 | G15: =IF(C16>0,C15/C16,0) -> 0 | H15: =IF(F15>=0.5,"✅ Stark/Strong",IF(F15>=0.33,"⚠️ Mittel/Medium","❌ Schwach/Weak")) -> ❌ Schwach/Weak | I15: SUMIFS(Revenue, Category, "Clothing")
A16: GESAMT/TOTAL | C16: =SUM(C13:C15) -> 795005 | D16: =SUM(D13:D15) -> 534235 | E16: =SUM(E13:E15) -> 260770 | F16: =IF(C16>0,E16/C16,0) -> 0.32801052
A24: ③ DIAGRAMME / CHARTS — Daten aus "📋 Annual Closing" 2011–2016 / Data from "Annual Closing"

Sheet 📋 Plan-Ist Vergleich
A1: 📋 PLAN-IST-VERGLEICH 2015 / BUDGET VS. ACTUAL 2015 — via SUMIFS
A2: DE: Umsatz Ist = SUMIFS aus Raw Data (nach Monat). Plan = hardcoded aus Modul 0. Alle abgeleiteten Werte (Abw., Marge, RAG) = Excel-Formeln. | EN: Revenue Actual = SUMIFS from Raw Data (by month). Budget = hardcoded from Module 0. All derived values (var., margin, RAG) = Excel formulas.
A3: 🔵 Blau/Blue = hardcoded Eingabe/input | 🟢 Grün/Green = Excel-Formel aus Raw Data / Excel formula from Raw Data | 🟡 Gelb/Yellow = Annahme änderbar / editable assumption | Formeln referenzieren: "🗃️ Raw Data (Sample)" / Formulas reference: "🗃️ Raw Data (Sample)"
A5: ① ANNAHMEN / ASSUMPTIONS — RAG-Schwellen (gelb = änderbar / yellow = editable)
A6: Grün-Schwelle / Green: | D6: 0.03 | E6: Rot-Schwelle / Red: | H6: -0.03 | I6: Materialität/Materiality: ±5%
A8: ② MONATLICHE ÜBERSICHT / MONTHLY OVERVIEW
A9: # | B9: Periode /Period | C9: Monat (Helper) | D9: Umsatz Ist /Revenue (SUMIFS) | E9: Umsatz Plan /Budget (hardcoded) | F9: Abw.abs /Var.abs (=D−E) | G9: Abw.% /Var.% (=F/E) | H9: RAG (IF-Formel) | I9: Marge% /Margin% (=GP/Rev) | J9: Ergebnis Ist /Profit (SUMIFS) | K9: Erg.Plan /Profit Budget (hardcoded)
A10: 1 | B10: 2015-01 | C10: 1 | D10: =SUMIFS('🗃️ Raw Data (Sample)'!J:J,'🗃️ Raw Data (Sample)'!A:A,">="&DATE(2015,C10,1),'🗃️ Raw Data (Sample)'!A:A,"<"&DATE(2015,C10+1,1)) -> 666938 | E10: 665780 | F10: =D10-E10 -> 1158 | G10: =IF(E10>0,F10/E10,0) -> 0.0017393133 | H10: =IF(G10>=$D$6,"🟢 Grün/Green",IF(G10>$H$6,"🟡 Amber","🔴 Rot/Red")) -> 🟡 Amber | I10: =IF(D10>0,J10/D10,0) -> 0.32865724 | J10: =SUMIFS('🗃️ Raw Data (Sample)'!K:K,'🗃️ Raw Data (Sample)'!A:A,">="&DATE(2015,C10,1),'🗃️ Raw Data (Sample)'!A:A,"<"&DATE(2015,C10+1,1)) -> 219194 | K10: 250333
A11: 2 | B11: 2015-02 | C11: 2 | D11: =SUMIFS('🗃️ Raw Data (Sample)'!J:J,'🗃️ Raw Data (Sample)'!A:A,">="&DATE(2015,C11,1),'🗃️ Raw Data (Sample)'!A:A,"<"&DATE(2015,C11+1,1)) -> 128067 | E11: 672878 | F11: =D11-E11 -> -544811 | G11: =IF(E11>0,F11/E11,0) -> -0.80967278 | H11: =IF(G11>=$D$6,"🟢 Grün/Green",IF(G11>$H$6,"🟡 Amber","🔴 Rot/Red")) -> 🔴 Rot/Red | I11: =IF(D11>0,J11/D11,0) -> 0.32464257 | J11: =SUMIFS('🗃️ Raw Data (Sample)'!K:K,'🗃️ Raw Data (Sample)'!A:A,">="&DATE(2015,C11,1),'🗃️ Raw Data (Sample)'!A:A,"<"&DATE(2015,C11+1,1)) -> 41576 | K11: 253002
A12: 3 | B12: 2015-03 | C12: 3 | D12: =SUMIFS('🗃️ Raw Data (Sample)'!J:J,'🗃️ Raw Data (Sample)'!A:A,">="&DATE(2015,C12,1),'🗃️ Raw Data (Sample)'!A:A,"<"&DATE(2015,C12+1,1)) -> 0 | E12: 712079 | F12: =D12-E12 -> -712079 | G12: =IF(E12>0,F12/E12,0) -> -1 | H12: =IF(G12>=$D$6,"🟢 Grün/Green",IF(G12>$H$6,"🟡 Amber","🔴 Rot/Red")) -> 🔴 Rot/Red | I12: =IF(D12>0,J12/D12,0) -> 0 | J12: =SUMIFS('🗃️ Raw Data (Sample)'!K:K,'🗃️ Raw Data (Sample)'!A:A,">="&DATE(2015,C12,1),'🗃️ Raw Data (Sample)'!A:A,"<"&DATE(2015,C12+1,1)) -> 0 | K12: 267742
A13: 4 | B13: 2015-04 | C13: 4 | D13: =SUMIFS('🗃️ Raw Data (Sample)'!J:J,'🗃️ Raw Data (Sample)'!A:A,">="&DATE(2015,C13,1),'🗃️ Raw Data (Sample)'!A:A,"<"&DATE(2015,C13+1,1)) -> 0 | E13: 728736 | F13: =D13-E13 -> -728736 | G13: =IF(E13>0,F13/E13,0) -> -1 | H13: =IF(G13>=$D$6,"🟢 Grün/Green",IF(G13>$H$6,"🟡 Amber","🔴 Rot/Red")) -> 🔴 Rot/Red | I13: =IF(D13>0,J13/D13,0) -> 0 | J13: =SUMIFS('🗃️ Raw Data (Sample)'!K:K,'🗃️ Raw Data (Sample)'!A:A,">="&DATE(2015,C13,1),'🗃️ Raw Data (Sample)'!A:A,"<"&DATE(2015,C13+1,1)) -> 0 | K13: 274005
A14: 5 | B14: 2015-05 | C14: 5 | D14: =SUMIFS('🗃️ Raw Data (Sample)'!J:J,'🗃️ Raw Data (Sample)'!A:A,">="&DATE(2015,C14,1),'🗃️ Raw Data (Sample)'!A:A,"<"&DATE(2015,C14+1,1)) -> 0 | E14: 901206 | F14: =D14-E14 -> -901206 | G14: =IF(E14>0,F14/E14,0) -> -1 | H14: =IF(G14>=$D$6,"🟢 Grün/Green",IF(G14>$H$6,"🟡 Amber","🔴 Rot/Red")) -> 🔴 Rot/Red | I14: =IF(D14>0,J14/D14,0) -> 0 | J14: =SUMIFS('🗃️ Raw Data (Sample)'!K:K,'🗃️ Raw Data (Sample)'!A:A,">="&DATE(2015,C14,1),'🗃️ Raw Data (Sample)'!A:A,"<"&DATE(2015,C14+1,1)) -> 0 | K14: 338853
A15: 6 | B15: 2015-06 | C15: 6 | D15: =SUMIFS('🗃️ Raw Data (Sample)'!J:J,'🗃️ Raw Data (Sample)'!A:A,">="&DATE(2015,C15,1),'🗃️ Raw Data (Sample)'!A:A,"<"&DATE(2015,C15+1,1)) -> 0 | E15: 786483 | F15: =D15-E15 -> -786483 | G15: =IF(E15>0,F15/E15,0) -> -1 | H15: =IF(G15>=$D$6,"🟢 Grün/Green",IF(G15>$H$6,"🟡 Amber","🔴 Rot/Red")) -> 🔴 Rot/Red | I15: =IF(D15>0,J15/D15,0) -> 0 | J15: =SUMIFS('🗃️ Raw Data (Sample)'!K:K,'🗃️ Raw Data (Sample)'!A:A,">="&DATE(2015,C15,1),'🗃️ Raw Data (Sample)'!A:A,"<"&DATE(2015,C15+1,1)) -> 0 | K15: 295718
A16: 7 | B16: 2015-07 | C16: 7 | D16: =SUMIFS('🗃️ Raw Data (Sample)'!J:J,'🗃️ Raw Data (Sample)'!A:A,">="&DATE(2015,C16,1),'🗃️ Raw Data (Sample)'!A:A,"<"&DATE(2015,C16+1,1)) -> 0 | E16: 1721640 | F16: =D16-E16 -> -1721640 | G16: =IF(E16>0,F16/E16,0) -> -1 | H16: =IF(G16>=$D$6,"🟢 Grün/Green",IF(G16>$H$6,"🟡 Amber","🔴 Rot/Red")) -> 🔴 Rot/Red | I16: =IF(D16>0,J16/D16,0) -> 0 | J16: =SUMIFS('🗃️ Raw Data (Sample)'!K:K,'🗃️ Raw Data (Sample)'!A:A,">="&DATE(2015,C16,1),'🗃️ Raw Data (Sample)'!A:A,"<"&DATE(2015,C16+1,1)) -> 0 | K16: 647337
A17: 8 | B17: 2015-08 | C17: 8 | D17: =SUMIFS('🗃️ Raw Data (Sample)'!J:J,'🗃️ Raw Data (Sample)'!A:A,">="&DATE(2015,C17,1),'🗃️ Raw Data (Sample)'!A:A,"<"&DATE(2015,C17+1,1)) -> 0 | E17: 2139961 | F17: =D17-E17 -> -2139961 | G17: =IF(E17>0,F17/E17,0) -> -1 | H17: =IF(G17>=$D$6,"🟢 Grün/Green",IF(G17>$H$6,"🟡 Amber","🔴 Rot/Red")) -> 🔴 Rot/Red | I17: =IF(D17>0,J17/D17,0) -> 0 | J17: =SUMIFS('🗃️ Raw Data (Sample)'!K:K,'🗃️ Raw Data (Sample)'!A:A,">="&DATE(2015,C17,1),'🗃️ Raw Data (Sample)'!A:A,"<"&DATE(2015,C17+1,1)) -> 0 | K17: 804625
A18: 9 | B18: 2015-09 | C18: 9 | D18: =SUMIFS('🗃️ Raw Data (Sample)'!J:J,'🗃️ Raw Data (Sample)'!A:A,">="&DATE(2015,C18,1),'🗃️ Raw Data (Sample)'!A:A,"<"&DATE(2015,C18+1,1)) -> 0 | E18: 2459901 | F18: =D18-E18 -> -2459901 | G18: =IF(E18>0,F18/E18,0) -> -1 | H18: =IF(G18>=$D$6,"🟢 Grün/Green",IF(G18>$H$6,"🟡 Amber","🔴 Rot/Red")) -> 🔴 Rot/Red | I18: =IF(D18>0,J18/D18,0) -> 0 | J18: =SUMIFS('🗃️ Raw Data (Sample)'!K:K,'🗃️ Raw Data (Sample)'!A:A,">="&DATE(2015,C18,1),'🗃️ Raw Data (Sample)'!A:A,"<"&DATE(2015,C18+1,1)) -> 0 | K18: 924923
A19: 10 | B19: 2015-10 | C19: 10 | D19: =SUMIFS('🗃️ Raw Data (Sample)'!J:J,'🗃️ Raw Data (Sample)'!A:A,">="&DATE(2015,C19,1),'🗃️ Raw Data (Sample)'!A:A,"<"&DATE(2015,C19+1,1)) -> 0 | E19: 2538826 | F19: =D19-E19 -> -2538826 | G19: =IF(E19>0,F19/E19,0) -> -1 | H19: =IF(G19>=$D$6,"🟢 Grün/Green",IF(G19>$H$6,"🟡 Amber","🔴 Rot/Red")) -> 🔴 Rot/Red | I19: =IF(D19>0,J19/D19,0) -> 0 | J19: =SUMIFS('🗃️ Raw Data (Sample)'!K:K,'🗃️ Raw Data (Sample)'!A:A,">="&DATE(2015,C19,1),'🗃️ Raw Data (Sample)'!A:A,"<"&DATE(2015,C19+1,1)) -> 0 | K19: 954599
A20: 11 | B20: 2015-11 | C20: 11 | D20: =SUMIFS('🗃️ Raw Data (Sample)'!J:J,'🗃️ Raw Data (Sample)'!A:A,">="&DATE(2015,C20,1),'🗃️ Raw Data (Sample)'!A:A,"<"&DATE(2015,C20+1,1)) -> 0 | E20: 2835230 | F20: =D20-E20 -> -2835230 | G20: =IF(E20>0,F20/E20,0) -> -1 | H20: =IF(G20>=$D$6,"🟢 Grün/Green",IF(G20>$H$6,"🟡 Amber","🔴 Rot/Red")) -> 🔴 Rot/Red | I20: =IF(D20>0,J20/D20,0) -> 0 | J20: =SUMIFS('🗃️ Raw Data (Sample)'!K:K,'🗃️ Raw Data (Sample)'!A:A,">="&DATE(2015,C20,1),'🗃️ Raw Data (Sample)'!A:A,"<"&DATE(2015,C20+1,1)) -> 0 | K20: 1066046
A21: 12 | B21: 2015-12 | C21: 12 | D21: =SUMIFS('🗃️ Raw Data (Sample)'!J:J,'🗃️ Raw Data (Sample)'!A:A,">="&DATE(2015,C21,1),'🗃️ Raw Data (Sample)'!A:A,"<"&DATE(2016,1,1)) -> 0 | E21: 3849604 | F21: =D21-E21 -> -3849604 | G21: =IF(E21>0,F21/E21,0) -> -1 | H21: =IF(G21>=$D$6,"🟢 Grün/Green",IF(G21>$H$6,"🟡 Amber","🔴 Rot/Red")) -> 🔴 Rot/Red | I21: =IF(D21>0,J21/D21,0) -> 0 | J21: =SUMIFS('🗃️ Raw Data (Sample)'!K:K,'🗃️ Raw Data (Sample)'!A:A,">="&DATE(2015,C21,1),'🗃️ Raw Data (Sample)'!A:A,"<"&DATE(2016,1,1)) -> 0 | K21: 1447451
A22: GESAMT 2015 / TOTAL 2015 | D22: =SUM(D10:D21) -> 795005 | E22: =SUM(E10:E21) -> 20012324 | F22: =SUM(F10:F21) -> -19217319 | G22: =IF(E22>0,F22/E22,0) -> -0.96027423 | I22: =IF(D22>0,J22/D22,0) -> 0.32801052 | J22: =SUM(J10:J21) -> 260770 | K22: =SUM(K10:K21) -> 7524634
A24: ③ FORMELERKLÄRUNG / FORMULA EXPLANATION
A25: Umsatz Ist (SUMIFS) | B25: =SUMIFS(Revenue, Datum, ">="&Monatsbeginn, Datum, "<"&Monatsende) ← SUMIFS nach Monat / by month | G25: Summiert Revenue wo Datum im jeweiligen Monat / Sums Revenue where date is in the given month
A26: Abw.% / Var.% | B26: =IF(Plan>0, (Ist-Plan)/Plan, 0) ← relative Abweichung / relative variance | G26: Relative Abweichung. IF schützt vor Division durch Null / IF protects division by zero
A27: RAG | B27: =IF(Abw%>=$D$6,"🟢",IF(Abw%>$H$6,"🟡","🔴")) ← RAG aus Schwellen / from thresholds | G27: Schwellen aus Annahmen-Zellen $D$6/$H$6 — änderbar! / Thresholds from assumption cells — editable!
A28: Bruttomarge / Margin% | B28: =IF(Revenue>0, Profit/Revenue, 0) ← Bruttomarge / gross margin | G28: Bruttoergebnis geteilt durch Umsatz / Gross Profit divided by Revenue

Sheet 🧮 Deckungsbeitrag
A1: 🧮 DECKUNGSBEITRAGSRECHNUNG / CONTRIBUTION MARGIN — via SUMIFS 2015
A2: DE: DB I und COGS via SUMIFS aus Raw Data. Fixkosten = Umsatz × Rate (Formel). DB II = DB I − Fixkosten (Formel). | EN: CM I and COGS via SUMIFS from Raw Data. Fixed costs = Revenue × Rate (formula). CM II = CM I − Fixed Costs (formula).
A3: 🔵 Blau/Blue = hardcoded Eingabe/input | 🟢 Grün/Green = Excel-Formel aus Raw Data / Excel formula from Raw Data | 🟡 Gelb/Yellow = Annahme änderbar / editable assumption | Formeln referenzieren: "🗃️ Raw Data (Sample)" / Formulas reference: "🗃️ Raw Data (Sample)"
A5: ① ANNAHMEN / ASSUMPTIONS
A6: Fixkostenrate / Fixed Cost Rate: | D6: 0.15 | E6: 15% des Umsatzes — in Zelle D6 änderbar / 15% of revenue — editable in cell D6
A8: ② NACH PRODUKTKATEGORIE / BY PRODUCT CATEGORY — SUMIFS(D:D, Kategorie)
A9: # | B9: Kategorie /Category | C9: Umsatz /Revenue (SUMIFS) | D9: Var.Kosten /COGS (SUMIFS) | E9: DB I / CM I (=C−D) | F9: Fixkosten /Fixed (=C×Rate) | G9: DB II / CM II (=E−F) | H9: DB-Quote% /CM Rate% (=E/C) | I9: Rev Share% (=C/ΣC) | J9: Formel-Beispiel /Formula Example
A10: 1 | B10: Accessories | C10: =SUMIFS('🗃️ Raw Data (Sample)'!J:J,'🗃️ Raw Data (Sample)'!D:D,B10) -> 0 | D10: =SUMIFS('🗃️ Raw Data (Sample)'!I:I,'🗃️ Raw Data (Sample)'!D:D,B10) -> 0 | E10: =C10-D10 -> 0 | F10: =ROUND(C10*$D$6,0) -> 0 | G10: =E10-F10 -> 0 | H10: =IF(C10>0,E10/C10,0) -> 0 | I10: =IF(C13>0,C10/C13,0) -> 0 | J10: SUMIFS(Revenue, Category, "Accessories")
A11: 2 | B11: Bikes | C11: =SUMIFS('🗃️ Raw Data (Sample)'!J:J,'🗃️ Raw Data (Sample)'!D:D,B11) -> 795005 | D11: =SUMIFS('🗃️ Raw Data (Sample)'!I:I,'🗃️ Raw Data (Sample)'!D:D,B11) -> 534235 | E11: =C11-D11 -> 260770 | F11: =ROUND(C11*$D$6,0) -> 119251 | G11: =E11-F11 -> 141519 | H11: =IF(C11>0,E11/C11,0) -> 0.32801052 | I11: =IF(C13>0,C11/C13,0) -> 1 | J11: SUMIFS(Revenue, Category, "Bikes")
A12: 3 | B12: Clothing | C12: =SUMIFS('🗃️ Raw Data (Sample)'!J:J,'🗃️ Raw Data (Sample)'!D:D,B12) -> 0 | D12: =SUMIFS('🗃️ Raw Data (Sample)'!I:I,'🗃️ Raw Data (Sample)'!D:D,B12) -> 0 | E12: =C12-D12 -> 0 | F12: =ROUND(C12*$D$6,0) -> 0 | G12: =E12-F12 -> 0 | H12: =IF(C12>0,E12/C12,0) -> 0 | I12: =IF(C13>0,C12/C13,0) -> 0 | J12: SUMIFS(Revenue, Category, "Clothing")
A13: GESAMT/TOTAL | C13: =SUM(C10:C12) -> 795005 | D13: =SUM(D10:D12) -> 534235 | E13: =SUM(E10:E12) -> 260770 | F13: =SUM(F10:F12) -> 119251 | G13: =SUM(G10:G12) -> 141519 | H13: =IF(C13>0,E13/C13,0) -> 0.32801052 | I13: 1
A15: ③ NACH LAND / BY COUNTRY — SUMIFS(B:B, Land/Country)
A16: # | B16: Land EN /Country | C16: Land DE /Land | D16: Umsatz /Revenue (SUMIFS) | E16: Var.Kosten /COGS (SUMIFS) | F16: DB I / CM I (=D−E) | G16: Fixkosten /Fixed (=D×Rate) | H16: DB II / CM II (=F−G) | I16: DB-Quote% /CM Rate% (=F/D) | J16: Formel-Beispiel /Formula Example
A17: 1 | B17: Australia | C17: Australien | D17: =SUMIFS('🗃️ Raw Data (Sample)'!J:J,'🗃️ Raw Data (Sample)'!B:B,B17) -> 294358 | E17: =SUMIFS('🗃️ Raw Data (Sample)'!I:I,'🗃️ Raw Data (Sample)'!B:B,B17) -> 208526 | F17: =D17-E17 -> 85832 | G17: =ROUND(D17*$D$6,0) -> 44154 | H17: =F17-G17 -> 41678 | I17: =IF(D17>0,F17/D17,0) -> 0.29159051 | J17: SUMIFS(Revenue, Country, "Australia")
A18: 2 | B18: Canada | C18: Kanada | D18: =SUMIFS('🗃️ Raw Data (Sample)'!J:J,'🗃️ Raw Data (Sample)'!B:B,B18) -> 33365 | E18: =SUMIFS('🗃️ Raw Data (Sample)'!I:I,'🗃️ Raw Data (Sample)'!B:B,B18) -> 19946 | F18: =D18-E18 -> 13419 | G18: =ROUND(D18*$D$6,0) -> 5005 | H18: =F18-G18 -> 8414 | I18: =IF(D18>0,F18/D18,0) -> 0.40218792 | J18: SUMIFS(Revenue, Country, "Canada")
A19: 3 | B19: France | C19: Frankreich | D19: =SUMIFS('🗃️ Raw Data (Sample)'!J:J,'🗃️ Raw Data (Sample)'!B:B,B19) -> 78468 | E19: =SUMIFS('🗃️ Raw Data (Sample)'!I:I,'🗃️ Raw Data (Sample)'!B:B,B19) -> 53836 | F19: =D19-E19 -> 24632 | G19: =ROUND(D19*$D$6,0) -> 11770 | H19: =F19-G19 -> 12862 | I19: =IF(D19>0,F19/D19,0) -> 0.3139114 | J19: SUMIFS(Revenue, Country, "France")
A20: 4 | B20: Germany | C20: Deutschland | D20: =SUMIFS('🗃️ Raw Data (Sample)'!J:J,'🗃️ Raw Data (Sample)'!B:B,B20) -> 76077 | E20: =SUMIFS('🗃️ Raw Data (Sample)'!I:I,'🗃️ Raw Data (Sample)'!B:B,B20) -> 50871 | F20: =D20-E20 -> 25206 | G20: =ROUND(D20*$D$6,0) -> 11412 | H20: =F20-G20 -> 13794 | I20: =IF(D20>0,F20/D20,0) -> 0.33132221 | J20: SUMIFS(Revenue, Country, "Germany")
A21: 5 | B21: United Kingdom | C21: Vereinigtes Königreich | D21: =SUMIFS('🗃️ Raw Data (Sample)'!J:J,'🗃️ Raw Data (Sample)'!B:B,B21) -> 106058 | E21: =SUMIFS('🗃️ Raw Data (Sample)'!I:I,'🗃️ Raw Data (Sample)'!B:B,B21) -> 66620 | F21: =D21-E21 -> 39438 | G21: =ROUND(D21*$D$6,0) -> 15909 | H21: =F21-G21 -> 23529 | I21: =IF(D21>0,F21/D21,0) -> 0.37185314 | J21: SUMIFS(Revenue, Country, "United Kingdom")
A22: 6 | B22: United States | C22: Vereinigte Staaten | D22: =SUMIFS('🗃️ Raw Data (Sample)'!J:J,'🗃️ Raw Data (Sample)'!B:B,B22) -> 206679 | E22: =SUMIFS('🗃️ Raw Data (Sample)'!I:I,'🗃️ Raw Data (Sample)'!B:B,B22) -> 134436 | F22: =D22-E22 -> 72243 | G22: =ROUND(D22*$D$6,0) -> 31002 | H22: =F22-G22 -> 41241 | I22: =IF(D22>0,F22/D22,0) -> 0.34954204 | J22: SUMIFS(Revenue, Country, "United States")
A23: GESAMT/TOTAL | D23: =SUM(D17:D22) -> 795005 | E23: =SUM(E17:E22) -> 534235 | F23: =SUM(F17:F22) -> 260770 | G23: =SUM(G17:G22) -> 119252 | H23: =SUM(H17:H22) -> 141518 | I23: =IF(D23>0,F23/D23,0) -> 0.32801052
A25: ④ FORMELERKLÄRUNG / FORMULA EXPLANATION
A26: SUMIFS — Kategorie/Category | B26: =SUMIFS(Revenue_Spalte, Kategorie_Spalte, "Bikes") ← Kategorie-Filter / category filter | F26: Summiert Revenue wo Kategorie = "Bikes" / Sums Revenue where Category = "Bikes"
A27: SUMIFS — Land/Country | B27: =SUMIFS(Revenue_Spalte, Land_Spalte, "Germany") ← Länder-Filter / country filter | F27: Summiert Revenue wo Land = "Germany" / Sums Revenue where Country = "Germany"
A28: DB I / CM I | B28: =Umsatz - Var.Kosten → z.B. =C10-D10 ← DB I Berechnung / CM I calculation | F28: Deckungsbeitrag I = Umsatz minus variable Kosten (COGS) / CM I = Revenue minus COGS
A29: Fixkosten / Fixed Costs | B29: =ROUND(Umsatz × $D$6, 0) → z.B. =ROUND(C10*$D$6,0) ← Fixkosten / fixed costs | F29: 15% des Umsatzes (Rate in $D$6 änderbar) / 15% of revenue (rate editable in $D$6)
A30: DB II / CM II | B30: =DB I - Fixkosten → z.B. =E10-F10 ← DB II Berechnung / CM II calculation | F30: Deckungsbeitrag II nach Abzug der Fixkosten / CM II after deducting fixed costs

Sheet 📈 Rolling Forecast
A1: 📈 ROLLING FORECAST 2015 — SUMIFS + Forecast-Formel / Formula
A2: DE: Ist-Werte via SUMIFS aus Raw Data. Forecast = Ø letzter 3 Ist-Monate × Saisonfaktor (Formel). Plan = hardcoded aus Modul 0. | EN: Actuals via SUMIFS from Raw Data. Forecast = Avg last 3 actuals × seasonality factor (formula). Budget = hardcoded from Module 0.
A3: 🔵 Blau/Blue = hardcoded Eingabe/input | 🟢 Grün/Green = Excel-Formel aus Raw Data / Excel formula from Raw Data | 🟡 Gelb/Yellow = Annahme änderbar / editable assumption | Formeln referenzieren: "🗃️ Raw Data (Sample)" / Formulas reference: "🗃️ Raw Data (Sample)"
A5: ① ANNAHMEN / ASSUMPTIONS
A6: Cutoff-Monat / Cutoff Month: | D6: 9 | E6: Letzter Ist-Monat (1–12) — änderbar! / Last actual month (1–12) — editable!
A7: Saisonfaktoren 2013 / Seasonality 2013: | D7: In Zeilen 10–21 hinterlegt (Spalte E) / Stored in rows 10–21 (column E) — aus/from 2013-Daten
A9: ② MONATLICHE ÜBERSICHT / MONTHLY OVERVIEW
A10: # | B10: Periode /Period | C10: Monat (Helper) | D10: Umsatz Ist /Revenue (SUMIFS) | E10: Saisonfaktor /Season Factor (2013, hardcoded) | F10: Umsatz Plan /Budget (hardcoded) | G10: Forecast (=Ø×Saison) IF Monat>Cutoff | H10: Ist oder FC /Actual or FC (IF-Formel) | I10: Abw.Ist/Plan /Act vs Budget (=D−F)/F | J10: Kommentar / Comment
A11: 1 | B11: 2015-01 | C11: 1 | D11: =IF(C11<=$D$6,SUMIFS('🗃️ Raw Data (Sample)'!J:J,'🗃️ Raw Data (Sample)'!A:A,">="&DATE(2015,C11,1),'🗃️ Raw Data (Sample)'!A:A,"<"&DATE(2015,C11+1,1)),"") -> 666938 | E11: 0.63 | F11: 665780 | G11: =IF(C11>$D$6,ROUND(AVERAGE(D17:D19)*E11,0),"") | H11: =IF(C11<=$D$6,D11,G11) -> 666938 | I11: =IF(AND(C11<=$D$6,D11<>""),IF(F11>0,(D11-F11)/F11,0),"") -> 0.0017393133 | J11: ✅ Ist-Wert via SUMIFS / Actual via SUMIFS
A12: 2 | B12: 2015-02 | C12: 2 | D12: =IF(C12<=$D$6,SUMIFS('🗃️ Raw Data (Sample)'!J:J,'🗃️ Raw Data (Sample)'!A:A,">="&DATE(2015,C12,1),'🗃️ Raw Data (Sample)'!A:A,"<"&DATE(2015,C12+1,1)),"") -> 128067 | E12: 0.63 | F12: 672878 | G12: =IF(C12>$D$6,ROUND(AVERAGE(D17:D19)*E12,0),"") | H12: =IF(C12<=$D$6,D12,G12) -> 128067 | I12: =IF(AND(C12<=$D$6,D12<>""),IF(F12>0,(D12-F12)/F12,0),"") -> -0.80967278 | J12: ✅ Ist-Wert via SUMIFS / Actual via SUMIFS
A13: 3 | B13: 2015-03 | C13: 3 | D13: =IF(C13<=$D$6,SUMIFS('🗃️ Raw Data (Sample)'!J:J,'🗃️ Raw Data (Sample)'!A:A,">="&DATE(2015,C13,1),'🗃️ Raw Data (Sample)'!A:A,"<"&DATE(2015,C13+1,1)),"") -> 0 | E13: 0.71 | F13: 712079 | G13: =IF(C13>$D$6,ROUND(AVERAGE(D17:D19)*E13,0),"") | H13: =IF(C13<=$D$6,D13,G13) -> 0 | I13: =IF(AND(C13<=$D$6,D13<>""),IF(F13>0,(D13-F13)/F13,0),"") -> -1 | J13: ✅ Ist-Wert via SUMIFS / Actual via SUMIFS
A14: 4 | B14: 2015-04 | C14: 4 | D14: =IF(C14<=$D$6,SUMIFS('🗃️ Raw Data (Sample)'!J:J,'🗃️ Raw Data (Sample)'!A:A,">="&DATE(2015,C14,1),'🗃️ Raw Data (Sample)'!A:A,"<"&DATE(2015,C14+1,1)),"") -> 0 | E14: 0.75 | F14: 728736 | G14: =IF(C14>$D$6,ROUND(AVERAGE(D17:D19)*E14,0),"") | H14: =IF(C14<=$D$6,D14,G14) -> 0 | I14: =IF(AND(C14<=$D$6,D14<>""),IF(F14>0,(D14-F14)/F14,0),"") -> -1 | J14: ✅ Ist-Wert via SUMIFS / Actual via SUMIFS
